Workbook

Sheet Worksheet
A1: Referral Date | B1: Referred By | C1: NHI | D1: Patient Name | E1: DOB | F1: Department | G1: Added to Waitlist Date | H1: Surgeon | I1: FSA Date | J1: Health Target Eligible
A2: 44905 | B2: Hilary Trump | C2: QDX4955 | D2: Spense Pringuer | E2: 26343 | F2: General Surgery | G2: 44910 | H2: Simon Frampton | I2: 44953 | J2: Yes
A3: 45069 | B3: Bill Key | C3: ECP7715 | D3: Shirline Van der Kruys | E3: 33965 | F3: Cardiothoracic | G3: 45073 | H3: Peri Duffy | I3: 45095 | J3: Yes
A4: 44912 | B4: Donald Clinton | C4: ZIK8925 | D4: Chev Eckels | E4: 18737 | F4: Cardiothoracic | G4: 44915 | H4: Steve Renison | I4: 44971 | J4: Yes
A5: 45055 | B5: Donald Clinton | C5: LTS6784 | D5: Rik Futty | E5: 22765 | F5: Plastics | G5: 45055 | H5: Richard Cain | I5: 45122 | J5: Yes
A6: 45069 | B6: Hilary Trump | C6: HGM6173 | D6: Emalia Killen | E6: 32802 | F6: Plastics | G6: 45076 | H6: Philip Mitchell | I6: 45121 | J6: Yes
A7: 44817 | B7: Amit Oliver | C7: CEV6132 | D7: Rudiger Endean | E7: 23786 | F7: Orthopaedics | G7: 44817 | H7: Evelyn Rae | I7: 44893 | J7: No
A8: 44935 | B8: Lesley Young | C8: PGJ7161 | D8: Beverie Robez | E8: 24871 | F8: Orthopaedics | G8: 44936 | H8: Evelyn Rae | I8: 45029 | J8: Yes
A9: 44808 | B9: Bill Key | C9: NKX8076 | D9: Donall Ricciardo | E9: 17827 | F9: Cardiothoracic | G9: 44815 | H9: Steve Renison | I9: 44871 | J9: Yes
A10: 44877 | B10: John English | C10: MXC8908 | D10: Timotheus Laven | E10: 27605 | F10: Cardiothoracic | G10: 44879 | H10: Steve Renison | I10: 44925 | J10: Yes
A11: 44928 | B11: Bill Key | C11: NTQ8299 | D11: Aluino Spelling | E11: 39645 | F11: Plastics | G11: 44932 | H11: Greta McLean | I11: 44991 | J11: Yes
A12: 45091 | B12: Ralph Smith | C12: QNE4372 | D12: Elvera Peasby | E12: 38646 | F12: Paediatric Surgery | G12: 45098 | H12: Nabaz Sayeed | J12: Yes
A13: 44911 | B13: Bill Key | C13: GIR5104 | D13: Vitia Goodlake | E13: 20984 | F13: Plastics | G13: 44914 | H13: Philip Mitchell | I13: 44988 | J13: Yes
A14: 44771 | B14: Lesley Young | C14: XKD2272 | D14: Sally Bargery | E14: 29458 | F14: General Surgery | G14: 44772 | H14: John Martin | I14: 44861 | J14: Yes
A15: 44972 | B15: Lesley Young | C15: DVX6602 | D15: Brig Ovendale | E15: 41392 | F15: Paediatric Surgery | G15: 44978 | H15: Michael Lewis | I15: 45016 | J15: Yes
A16: 45025 | B16: Linda Moore | C16: JIB5920 | D16: Syman Badcock | E16: 27857 | F16: General Surgery | G16: 45028 | H16: Karen Reid | I16: 45096 | J16: Yes
A17: 45007 | B17: Lesley Young | C17: YCX9278 | D17: Eugenie Hugueville | E17: 41785 | F17: Paediatric Surgery | G17: 45013 | H17: Michael Lewis | I17: 45051 | J17: Yes
A18: 45006 | B18: Bill Key | C18: LMV5416 | D18: Scottie Emms | E18: 22327 | F18: Plastics | G18: 45008 | H18: Philip Mitchell | I18: 45023 | J18: Yes
A19: 45022 | B19: Lesley Young | C19: YBB1095 | D19: Carlye Greenhead | E19: 42375 | F19: General Surgery | G19: 45027 | H19: Karen Reid | I19: 45065 | J19: Yes
A20: 44922 | B20: Michael Scott | C20: TBC7855 | D20: Vina Dimond | E20: 24627 | F20: Orthopaedics | G20: 44927 | H20: Lindsay Nelson | I20: 44987 | J20: Yes
A21: 44842 | B21: John Richards | C21: SXL9274 | D21: Samson Durbann | E21: 24573 | F21: Cardiothoracic | G21: 44846 | H21: Andy La Salle | I21: 44891 | J21: Yes
A22: 45035 | B22: Amit Oliver | C22: AUX6004 | D22: Rosalie Couroy | E22: 28403 | F22: Plastics | G22: 45040 | H22: Greta McLean | I22: 45070 | J22: Yes
A23: 45067 | B23: Lesley Young | C23: SEO7156 | D23: Harmony Goodings | E23: 37966 | F23: Paediatric Surgery | G23: 45067 | H23: Andrew Hood | I23: 45115 | J23: Yes
A24: 44874 | B24: Ralph Smith | C24: XUA5670 | D24: Niki Cousins | E24: 30916 | F24: Plastics | G24: 44880 | H24: Philip Mitchell | I24: 44911 | J24: Yes
... A43: 44807 | B43: Lesley Young | C43: ASD4088 | D43: Schuyler Willimot | E43: 20794 | F43: Cardiothoracic | G43: 44814 | H43: Andy La Salle | I43: 44889 | J43: Yes
A44: 45088 | B44: Donald Clinton | C44: GIQ8970 | D44: Whitney Lakeland | E44: 31726 | F44: General Surgery | G44: 45094 | H44: Karen Reid | J44: Yes
A45: 44915 | B45: Hilary Trump | C45: GEK5713 | D45: Lucias Karlsson | E45: 39384 | F45: Paediatric Surgery | G45: 44921 | H45: Nabaz Sayeed | I45: 44935 | J45: Yes
A46: 44839 | B46: Amit Oliver | C46: TGS0798 | D46: Simona Gerrets | E46: 32627 | F46: Plastics | G46: 44843 | H46: Greta McLean | I46: 44866 | J46: Yes
A47: 45050 | B47: Ralph Smith | C47: CYC0720 | D47: Nahum Drewet | E47: 22924 | F47: Cardiothoracic | G47: 45055 | H47: Andy La Salle | I47: 45102 | J47: Yes
A48: 44880 | B48: Ralph Smith | C48: SMH8891 | D48: Myrilla Jeandon | E48: 24876 | F48: Cardiothoracic | G48: 44880 | H48: Peri Duffy | I48: 44968 | J48: Yes
A49: 44777 | B49: Linda Moore | C49: FBG1062 | D49: Nancee Circuitt | E49: 22410 | F49: Cardiothoracic | G49: 44784 | H49: Peri Duffy | I49: 44859 | J49: Yes
A50: 45042 | B50: Hilary Trump | C50: XKX1957 | D50: Malory Houndesome | E50: 38319 | F50: Paediatric Surgery | G50: 45045 | H50: Nabaz Sayeed | I50: 45088 | J50: Yes
A51: 44813 | B51: Lesley Young | C51: AFH7245 | D51: Gar Strawbridge | E51: 30055 | F51: Cardiothoracic | G51: 44815 | H51: Steve Renison | I51: 44841 | J51: Yes
A52: 44937 | B52: Ralph Smith | C52: TXP4069 | D52: Sheffield Hares | E52: 38495 | F52: Paediatric Surgery | G52: 44942 | H52: Michael Lewis | I52: 45023 | J52: Yes
A53: 44972 | B53: Michael Scott | C53: MRL3058 | D53: Otho Duinkerk | E53: 27912 | F53: Cardiothoracic | G53: 44979 | H53: Steve Renison | I53: 45046 | J53: Yes
A54: 44754 | B54: Amit Oliver | C54: FVL8648 | D54: Ruby Manklow | E54: 28037 | F54: General Surgery | G54: 44754 | H54: John Martin | I54: 44771 | J54: Yes
A55: 44983 | B55: Hilary Trump | C55: GKY3212 | D55: Davida MacCurlye | E55: 24015 | F55: Plastics | G55: 44990 | H55: Greta McLean | I55: 45018 | J55: No
A56: 45022 | B56: Ralph Smith | C56: ETV6899 | D56: Abba Rusk | E56: 22510 | F56: General Surgery | G56: 45022 | H56: John Martin | I56: 45110 | J56: Yes
... A58: 44799 | B58: John English | C58: VFY9388 | D58: Cristobal Guyers | E58: 31525 | F58: Orthopaedics | G58: 44799 | H58: Evelyn Rae | I58: 44887 | J58: Yes
A59: 44946 | B59: Lesley Young | D59: Marcelia Jeffcoate | E59: 31398 | F59: Orthopaedics | G59: 44948 | H59: Lindsay Nelson | I59: 44979 | J59: Yes
...

Sheet Patient
A1: Pateint ID(PK) | B1: firstName | C1: lastName | D1: DOB
A2: =IF(C2<>"", "P-1" & (10 + ROW()-1), "") -> P-111 | C2: {=_xlfn._xlws.FILTER(Worksheet!D2:D500,Worksheet!D2:D500<>"")} -> Spense Pringuer | D2: {=_xlfn._xlws.FILTER(Worksheet!E2:E500,Worksheet!E2:E500<>"")} -> 26343
A3: =IF(C3<>"", "P-1" & (10 + ROW()-1), "") -> P-112 | C3: Shirline Van der Kruys | D3: 33965
A4: =IF(C4<>"", "P-1" & (10 + ROW()-1), "") -> P-113 | C4: Chev Eckels | D4: 18737
A5: =IF(C5<>"", "P-1" & (10 + ROW()-1), "") -> P-114 | C5: Rik Futty | D5: 22765
A6: =IF(C6<>"", "P-1" & (10 + ROW()-1), "") -> P-115 | C6: Emalia Killen | D6: 32802
A7: =IF(C7<>"", "P-1" & (10 + ROW()-1), "") -> P-116 | C7: Rudiger Endean | D7: 23786
A8: =IF(C8<>"", "P-1" & (10 + ROW()-1), "") -> P-117 | C8: Beverie Robez | D8: 24871
A9: =IF(C9<>"", "P-1" & (10 + ROW()-1), "") -> P-118 | C9: Donall Ricciardo | D9: 17827
A10: =IF(C10<>"", "P-1" & (10 + ROW()-1), "") -> P-119 | C10: Timotheus Laven | D10: 27605
A11: =IF(C11<>"", "P-1" & (10 + ROW()-1), "") -> P-120 | C11: Aluino Spelling | D11: 39645
A12: =IF(C12<>"", "P-1" & (10 + ROW()-1), "") -> P-121 | C12: Elvera Peasby | D12: 38646
A13: =IF(C13<>"", "P-1" & (10 + ROW()-1), "") -> P-122 | C13: Vitia Goodlake | D13: 20984
A14: =IF(C14<>"", "P-1" & (10 + ROW()-1), "") -> P-123 | C14: Sally Bargery | D14: 29458
... A79: =IF(C79<>"", "P-1" & (10 + ROW()-1), "") -> P-188 | C79: Morganne Baynom | D79: 18470
A80: =IF(C80<>"", "P-1" & (10 + ROW()-1), "") -> P-189 | C80: Graeme Fenemore | D80: 06/07/1756
A81: =IF(C81<>"", "P-1" & (10 + ROW()-1), "") -> P-190 | C81: Silas Lipgens | D81: 22604
A82: =IF(C82<>"", "P-1" & (10 + ROW()-1), "") -> P-191 | C82: Bonny Tremmil | D82: 27037
A83: =IF(C83<>"", "P-1" & (10 + ROW()-1), "") -> P-192 | C83: Ardelia Parmiter | D83: 25703
A84: =IF(C84<>"", "P-1" & (10 + ROW()-1), "") -> P-193 | C84: Cirillo Tuckwell | D84: 25561
A85: =IF(C85<>"", "P-1" & (10 + ROW()-1), "") -> P-194 | C85: Emyle Sokale | D85: 29091
A86: =IF(C86<>"", "P-1" & (10 + ROW()-1), "") -> P-195 | C86: Daryl Eastham | D86: 28516
A87: =IF(C87<>"", "P-1" & (10 + ROW()-1), "") -> P-196 | C87: Clovis Espadate | D87: 31784
A88: =IF(C88<>"", "P-1" & (10 + ROW()-1), "") -> P-197 | C88: Rebekkah Venes | D88: 40754
A89: =IF(C89<>"", "P-1" & (10 + ROW()-1), "") -> P-198 | C89: Wilone Tofanelli | D89: 38861
A90: =IF(C90<>"", "P-1" & (10 + ROW()-1), "") -> P-199 | C90: Hetti Joskowitz | D90: 32642
A91: =IF(C91<>"", "P-1" & (10 + ROW()-1), "") -> P-1100 | C91: Blinnie Olivari | D91: 25481
A92: =IF(C92<>"", "P-1" & (10 + ROW()-1), "") -> P-1101 | C92: Rufe Cardenoza | D92: 38277
... A154: =IF(C154<>"", "P-1" & (10 + ROW()-1), "") -> P-1163 | C154: Byron Beard | D154: 22574
A155: =IF(C155<>"", "P-1" & (10 + ROW()-1), "") -> P-1164 | C155: Gloria Hanson | D155: 11/04/1795
A156: =IF(C156<>"", "P-1" & (10 + ROW()-1), "") -> P-1165 | C156: David Roth | D156: 36212
A157: =IF(C157<>"", "P-1" & (10 + ROW()-1), "") -> P-1166 | C157: Macaulay Stephenson | D157: 32828
A158: =IF(C158<>"", "P-1" & (10 + ROW()-1), "") -> P-1167 | C158: Philip Lowery | D158: 38859
A159: =IF(C159<>"", "P-1" & (10 + ROW()-1), "") -> P-1168 | C159: Myles Lynch | D159: 18260
A160: =IF(C160<>"", "P-1" & (10 + ROW()-1), "") -> P-1169 | C160: Dai Smith | D160: 24594
A161: =IF(C161<>"", "P-1" & (10 + ROW()-1), "") -> P-1170 | C161: Myra Burks | D161: 33586
A162: =IF(C162<>"", "P-1" & (10 + ROW()-1), "") -> P-1171 | C162: Barbara Donaldson | D162: 39740
A163: =IF(C163<>"", "P-1" & (10 + ROW()-1), "") -> P-1172 | C163: Wayne Chapman | D163: 32538
A164: =IF(C164<>"", "P-1" & (10 + ROW()-1), "") -> P-1173 | C164: Upton Erickson | D164: 18631
A165: =IF(C165<>"", "P-1" & (10 + ROW()-1), "") -> P-1174 | C165: Wing Collier | D165: 19237
...

Sheet Department
A1: Departmaent ID(PK) | B1: Department Name
A2: =IF(B2<>"", "D-1" & (10 + ROW()-1), "") -> D-111 | B2: {=_xlfn.UNIQUE(_xlfn._xlws.FILTER(Worksheet!F2:F500, Worksheet!F2:F500<>""))} -> General Surgery
A3: =IF(B3<>"", "D-1" & (10 + ROW()-1), "") -> D-112 | B3: Cardiothoracic
A4: =IF(B4<>"", "D-1" & (10 + ROW()-1), "") -> D-113 | B4: Plastics
A5: =IF(B5<>"", "D-1" & (10 + ROW()-1), "") -> D-114 | B5: Orthopaedics
A6: =IF(B6<>"", "D-1" & (10 + ROW()-1), "") -> D-115 | B6: Paediatric Surgery

Sheet Surgeon
A1: Sergeon ID | B1: Surgeon Name
A2: =IF(B2<>"", "SID-1" & (10 + ROW()-1), "") -> SID-111 | B2: {=_xlfn.UNIQUE(_xlfn._xlws.FILTER(Worksheet!H2:H500, Worksheet!H2:H500<>""))} -> Simon Frampton
A3: =IF(B3<>"", "SID-1" & (10 + ROW()-1), "") -> SID-112 | B3: Peri Duffy
A4: =IF(B4<>"", "SID-1" & (10 + ROW()-1), "") -> SID-113 | B4: Steve Renison
A5: =IF(B5<>"", "SID-1" & (10 + ROW()-1), "") -> SID-114 | B5: Richard Cain
A6: =IF(B6<>"", "SID-1" & (10 + ROW()-1), "") -> SID-115 | B6: Philip Mitchell
A7: =IF(B7<>"", "SID-1" & (10 + ROW()-1), "") -> SID-116 | B7: Evelyn Rae
A8: =IF(B8<>"", "SID-1" & (10 + ROW()-1), "") -> SID-117 | B8: Greta McLean
A9: =IF(B9<>"", "SID-1" & (10 + ROW()-1), "") -> SID-118 | B9: Nabaz Sayeed
A10: =IF(B10<>"", "SID-1" & (10 + ROW()-1), "") -> SID-119 | B10: John Martin
A11: =IF(B11<>"", "SID-1" & (10 + ROW()-1), "") -> SID-120 | B11: Michael Lewis
A12: =IF(B12<>"", "SID-1" & (10 + ROW()-1), "") -> SID-121 | B12: Karen Reid
A13: =IF(B13<>"", "SID-1" & (10 + ROW()-1), "") -> SID-122 | B13: Lindsay Nelson
A14: =IF(B14<>"", "SID-1" & (10 + ROW()-1), "") -> SID-123 | B14: Andy La Salle
... A16: =IF(B16<>"", "SID-1" & (10 + ROW()-1), "") -> SID-125 | B16: Robert Patrick

Sheet Referal
A1: Referal ID | B1: Referal Name
A2: =IF(B2<>"", "RID-1" & (10 + ROW()-1), "") -> RID-111 | B2: {=_xlfn.UNIQUE(_xlfn._xlws.FILTER(Worksheet!B2:B500, Worksheet!B2:B500 <>""))} -> Hilary Trump
A3: =IF(B3<>"", "RID-1" & (10 + ROW()-1), "") -> RID-112 | B3: Bill Key
A4: =IF(B4<>"", "RID-1" & (10 + ROW()-1), "") -> RID-113 | B4: Donald Clinton
A5: =IF(B5<>"", "RID-1" & (10 + ROW()-1), "") -> RID-114 | B5: Amit Oliver
A6: =IF(B6<>"", "RID-1" & (10 + ROW()-1), "") -> RID-115 | B6: Lesley Young
A7: =IF(B7<>"", "RID-1" & (10 + ROW()-1), "") -> RID-116 | B7: John English
A8: =IF(B8<>"", "RID-1" & (10 + ROW()-1), "") -> RID-117 | B8: Ralph Smith
A9: =IF(B9<>"", "RID-1" & (10 + ROW()-1), "") -> RID-118 | B9: Linda Moore
A10: =IF(B10<>"", "RID-1" & (10 + ROW()-1), "") -> RID-119 | B10: Michael Scott
A11: =IF(B11<>"", "RID-1" & (10 + ROW()-1), "") -> RID-120 | B11: John Richards
A12: =IF(B12<>"", "RID-1" & (10 + ROW()-1), "")
A13: =IF(B13<>"", "RID-1" & (10 + ROW()-1), "")
A14: =IF(B14<>"", "RID-1" & (10 + ROW()-1), "")
A15: =IF(B15<>"", "RID-1" & (10 + ROW()-1), "")
A16: =IF(B16<>"", "RID-1" & (10 + ROW()-1), "")
A17: =IF(B17<>"", "RID-1" & (10 + ROW()-1), "")
A18: =IF(B18<>"", "RID-1" & (10 + ROW()-1), "")
A19: =IF(B19<>"", "RID-1" & (10 + ROW()-1), "")
A20: =IF(B20<>"", "RID-1" & (10 + ROW()-1), "")
A21: =IF(B21<>"", "RID-1" & (10 + ROW()-1), "")
A22: =IF(B22<>"", "RID-1" & (10 + ROW()-1), "")
A23: =IF(B23<>"", "RID-1" & (10 + ROW()-1), "")
... A500: =IF(B500<>"", "RID-1" & (10 + ROW()-1), "")

Sheet 1NF
A1: REFERAL ID | B1: PATIENT ID

Sheet Sheet2
A1: 1 | B1: 37257
A2: 2 | B2: 37258
A3: 3 | B3: 37259
A4: 4 | B4: 37260
A5: 5 | B5: 37261
A6: 6 | B6: 37262
A7: 7 | B7: 37263
A8: 8 | B8: 37264
A9: 9 | B9: 37265
A10: 10 | B10: 37266
A11: 11 | B11: 37267
A12: 12 | B12: 37268
... A2330: 2330 | B2330: 39586
